/Library/Developer/CommandLineTools/usr/bin/python3: can't open file '/Users/vir/Documents/GitHub/autocommit-bot/auto_commit.py': [Errno 1] Operation not permitted
/Library/Developer/CommandLineTools/usr/bin/python3: can't open file '/Users/vir/Documents/GitHub/autocommit-bot/auto_commit.py': [Errno 1] Operation not permitted
/Library/Developer/CommandLineTools/usr/bin/python3: can't open file '/Users/vir/Documents/GitHub/autocommit-bot/auto_commit.py': [Errno 1] Operation not permitted
/Library/Developer/CommandLineTools/usr/bin/python3: can't open file '/Users/vir/Documents/GitHub/autocommit-bot/auto_commit.py': [Errno 1] Operation not permitted
/Library/Developer/CommandLineTools/usr/bin/python3: can't open file '/Users/vir/Documents/GitHub/autocommit-bot/auto_commit.py': [Errno 1] Operation not permitted
/Library/Developer/CommandLineTools/usr/bin/python3: can't open file '/Users/vir/Documents/GitHub/autocommit-bot/auto_commit.py': [Errno 1] Operation not permitted
/Library/Developer/CommandLineTools/usr/bin/python3: can't open file '/Users/vir/Documents/GitHub/autocommit-bot/auto_commit.py': [Errno 1] Operation not permitted
Traceback (most recent call last):
  File "/Users/vir/Documents/GitHub/autocommit-bot/auto_commit.py", line 28, in <module>
    origin.push()
  File "/Users/vir/anaconda3/lib/python3.10/site-packages/git/remote.py", line 1210, in push
    return self._get_push_info(proc, progress, kill_after_timeout=kill_after_timeout)
  File "/Users/vir/anaconda3/lib/python3.10/site-packages/git/remote.py", line 975, in _get_push_info
    proc.wait(stderr=stderr_text)
  File "/Users/vir/anaconda3/lib/python3.10/site-packages/git/cmd.py", line 834, in wait
    raise GitCommandError(remove_password_if_present(self.args), status, errstr)
git.exc.GitCommandError: Cmd('git') failed due to: exit code(128)
  cmdline: git push --porcelain -- origin
  stderr: 'fatal: could not read Username for 'https://github.com': Device not configured'
Traceback (most recent call last):
  File "/Users/vir/Documents/GitHub/autocommit-bot/auto_commit.py", line 28, in <module>
    origin.push()
  File "/Users/vir/anaconda3/lib/python3.10/site-packages/git/remote.py", line 1210, in push
    return self._get_push_info(proc, progress, kill_after_timeout=kill_after_timeout)
  File "/Users/vir/anaconda3/lib/python3.10/site-packages/git/remote.py", line 975, in _get_push_info
    proc.wait(stderr=stderr_text)
  File "/Users/vir/anaconda3/lib/python3.10/site-packages/git/cmd.py", line 834, in wait
    raise GitCommandError(remove_password_if_present(self.args), status, errstr)
git.exc.GitCommandError: Cmd('git') failed due to: exit code(128)
  cmdline: git push --porcelain -- origin
  stderr: 'fatal: could not read Username for 'https://github.com': Device not configured'
Traceback (most recent call last):
  File "/Users/vir/Documents/GitHub/autocommit-bot/auto_commit.py", line 28, in <module>
    origin.push()
  File "/Users/vir/anaconda3/lib/python3.10/site-packages/git/remote.py", line 1210, in push
    return self._get_push_info(proc, progress, kill_after_timeout=kill_after_timeout)
  File "/Users/vir/anaconda3/lib/python3.10/site-packages/git/remote.py", line 975, in _get_push_info
    proc.wait(stderr=stderr_text)
  File "/Users/vir/anaconda3/lib/python3.10/site-packages/git/cmd.py", line 834, in wait
    raise GitCommandError(remove_password_if_present(self.args), status, errstr)
git.exc.GitCommandError: Cmd('git') failed due to: exit code(128)
  cmdline: git push --porcelain -- origin
  stderr: 'fatal: could not read Username for 'https://github.com': Device not configured'
Traceback (most recent call last):
  File "/Users/vir/Documents/GitHub/autocommit-bot/auto_commit.py", line 28, in <module>
    origin.push()
  File "/Users/vir/anaconda3/lib/python3.10/site-packages/git/remote.py", line 1210, in push
    return self._get_push_info(proc, progress, kill_after_timeout=kill_after_timeout)
  File "/Users/vir/anaconda3/lib/python3.10/site-packages/git/remote.py", line 975, in _get_push_info
    proc.wait(stderr=stderr_text)
  File "/Users/vir/anaconda3/lib/python3.10/site-packages/git/cmd.py", line 834, in wait
    raise GitCommandError(remove_password_if_present(self.args), status, errstr)
git.exc.GitCommandError: Cmd('git') failed due to: exit code(128)
  cmdline: git push --porcelain -- origin
  stderr: 'fatal: could not read Username for 'https://github.com': Device not configured'
Traceback (most recent call last):
  File "/Users/vir/Documents/GitHub/autocommit-bot/auto_commit.py", line 28, in <module>
    origin.push()
  File "/Users/vir/anaconda3/lib/python3.10/site-packages/git/remote.py", line 1210, in push
    return self._get_push_info(proc, progress, kill_after_timeout=kill_after_timeout)
  File "/Users/vir/anaconda3/lib/python3.10/site-packages/git/remote.py", line 975, in _get_push_info
    proc.wait(stderr=stderr_text)
  File "/Users/vir/anaconda3/lib/python3.10/site-packages/git/cmd.py", line 834, in wait
    raise GitCommandError(remove_password_if_present(self.args), status, errstr)
git.exc.GitCommandError: Cmd('git') failed due to: exit code(128)
  cmdline: git push --porcelain -- origin
  stderr: 'fatal: could not read Username for 'https://github.com': Device not configured'
